2025-04-02 13:02:09,032 - INFO - HTTP Request: POST https://api.groq.com/openai/v1/chat/completions "HTTP/1.1 404 Not Found"
2025-04-02 13:02:09,039 - ERROR - Classification error: Error code: 404 - {'error': {'message': 'The model `llama-3-70b-8192` does not exist or you do not have access to it.', 'type': 'invalid_request_error', 'code': 'model_not_found'}}
2025-04-02 13:02:09,376 - INFO - HTTP Request: POST https://api.groq.com/openai/v1/chat/completions "HTTP/1.1 404 Not Found"
2025-04-02 13:02:09,377 - ERROR - Classification error: Error code: 404 - {'error': {'message': 'The model `llama-3-70b-8192` does not exist or you do not have access to it.', 'type': 'invalid_request_error', 'code': 'model_not_found'}}
2025-04-02 13:02:09,703 - INFO - HTTP Request: POST https://api.groq.com/openai/v1/chat/completions "HTTP/1.1 404 Not Found"
2025-04-02 13:02:09,706 - ERROR - Classification error: Error code: 404 - {'error': {'message': 'The model `llama-3-70b-8192` does not exist or you do not have access to it.', 'type': 'invalid_request_error', 'code': 'model_not_found'}}
2025-04-02 13:02:10,037 - INFO - HTTP Request: POST https://api.groq.com/openai/v1/chat/completions "HTTP/1.1 404 Not Found"
2025-04-02 13:02:10,040 - ERROR - Classification error: Error code: 404 - {'error': {'message': 'The model `llama-3-70b-8192` does not exist or you do not have access to it.', 'type': 'invalid_request_error', 'code': 'model_not_found'}}
2025-04-02 13:02:10,365 - INFO - HTTP Request: POST https://api.groq.com/openai/v1/chat/completions "HTTP/1.1 404 Not Found"
2025-04-02 13:02:10,368 - ERROR - Classification error: Error code: 404 - {'error': {'message': 'The model `llama-3-70b-8192` does not exist or you do not have access to it.', 'type': 'invalid_request_error', 'code': 'model_not_found'}}
2025-04-02 13:02:57,630 - INFO - Processing query: Can you guide me about visitor guides...
2025-04-02 13:02:58,146 - INFO - HTTP Request: POST https://api.groq.com/openai/v1/chat/completions "HTTP/1.1 404 Not Found"
2025-04-02 13:02:58,148 - ERROR - Classification error: Error code: 404 - {'error': {'message': 'The model `llama-3-70b-8192` does not exist or you do not have access to it.', 'type': 'invalid_request_error', 'code': 'model_not_found'}}
2025-04-02 13:03:00,060 - INFO - Routed to Live Operator in 2.43 seconds
2025-04-02 13:03:00,063 - INFO - Call handled - Classification: HUMAN | Status: success
2025-04-02 13:03:22,853 - INFO - Processing query: What are your charges per day...
2025-04-02 13:03:23,263 - INFO - HTTP Request: POST https://api.groq.com/openai/v1/chat/completions "HTTP/1.1 404 Not Found"
2025-04-02 13:03:23,266 - ERROR - Classification error: Error code: 404 - {'error': {'message': 'The model `llama-3-70b-8192` does not exist or you do not have access to it.', 'type': 'invalid_request_error', 'code': 'model_not_found'}}
2025-04-02 13:03:24,297 - INFO - Routed to Live Operator in 1.44 seconds
2025-04-02 13:03:24,302 - INFO - Call handled - Classification: HUMAN | Status: success
2025-04-02 13:03:56,261 - INFO - Processing query: I want to book an appointment...
2025-04-02 13:03:56,917 - INFO - HTTP Request: POST https://api.groq.com/openai/v1/chat/completions "HTTP/1.1 404 Not Found"
2025-04-02 13:03:56,920 - ERROR - Classification error: Error code: 404 - {'error': {'message': 'The model `llama-3-70b-8192` does not exist or you do not have access to it.', 'type': 'invalid_request_error', 'code': 'model_not_found'}}
2025-04-02 13:03:58,634 - INFO - Routed to Live Operator in 2.37 seconds
2025-04-02 13:03:58,635 - INFO - Call handled - Classification: HUMAN | Status: success
2025-04-02 13:04:37,579 - INFO - Processing query: Want to book appoinymrnt...
2025-04-02 13:04:38,331 - INFO - HTTP Request: POST https://api.groq.com/openai/v1/chat/completions "HTTP/1.1 404 Not Found"
2025-04-02 13:04:38,333 - ERROR - Classification error: Error code: 404 - {'error': {'message': 'The model `llama-3-70b-8192` does not exist or you do not have access to it.', 'type': 'invalid_request_error', 'code': 'model_not_found'}}
2025-04-02 13:04:40,029 - WARNING - Connection failed to Live Operator
2025-04-02 13:04:40,031 - ERROR - System error: 'response'
2025-04-02 13:04:53,960 - INFO - Processing query: Want to book an appointment...
2025-04-02 13:04:54,690 - INFO - HTTP Request: POST https://api.groq.com/openai/v1/chat/completions "HTTP/1.1 404 Not Found"
2025-04-02 13:04:54,692 - ERROR - Classification error: Error code: 404 - {'error': {'message': 'The model `llama-3-70b-8192` does not exist or you do not have access to it.', 'type': 'invalid_request_error', 'code': 'model_not_found'}}
2025-04-02 13:04:56,317 - INFO - Routed to Live Operator in 2.36 seconds
2025-04-02 13:04:56,318 - INFO - Call handled - Classification: HUMAN | Status: success
2025-04-02 13:07:43,883 - ERROR - System error: 
2025-04-02 13:07:49,938 - INFO - HTTP Request: POST https://api.groq.com/openai/v1/chat/completions "HTTP/1.1 404 Not Found"
2025-04-02 13:07:49,941 - ERROR - Classification error: Error code: 404 - {'error': {'message': 'The model `llama-3-70b-8192` does not exist or you do not have access to it.', 'type': 'invalid_request_error', 'code': 'model_not_found'}}
2025-04-02 13:07:50,197 - INFO - HTTP Request: POST https://api.groq.com/openai/v1/chat/completions "HTTP/1.1 404 Not Found"
2025-04-02 13:07:50,200 - ERROR - Classification error: Error code: 404 - {'error': {'message': 'The model `llama-3-70b-8192` does not exist or you do not have access to it.', 'type': 'invalid_request_error', 'code': 'model_not_found'}}
2025-04-02 13:07:50,455 - INFO - HTTP Request: POST https://api.groq.com/openai/v1/chat/completions "HTTP/1.1 404 Not Found"
2025-04-02 13:07:50,457 - ERROR - Classification error: Error code: 404 - {'error': {'message': 'The model `llama-3-70b-8192` does not exist or you do not have access to it.', 'type': 'invalid_request_error', 'code': 'model_not_found'}}
2025-04-02 13:07:50,710 - INFO - HTTP Request: POST https://api.groq.com/openai/v1/chat/completions "HTTP/1.1 404 Not Found"
2025-04-02 13:07:50,712 - ERROR - Classification error: Error code: 404 - {'error': {'message': 'The model `llama-3-70b-8192` does not exist or you do not have access to it.', 'type': 'invalid_request_error', 'code': 'model_not_found'}}
2025-04-02 13:07:51,043 - INFO - HTTP Request: POST https://api.groq.com/openai/v1/chat/completions "HTTP/1.1 404 Not Found"
2025-04-02 13:07:51,045 - ERROR - Classification error: Error code: 404 - {'error': {'message': 'The model `llama-3-70b-8192` does not exist or you do not have access to it.', 'type': 'invalid_request_error', 'code': 'model_not_found'}}
2025-04-02 13:08:12,205 - INFO - Processing query: I want to schedule an appoitnment...
2025-04-02 13:08:12,942 - INFO - Routed to Appointment Desk in 0.74 seconds
2025-04-02 13:08:12,946 - INFO - Call handled - Classification: SQL | Status: success
2025-04-02 13:08:34,655 - INFO - Processing query: What are the care instructions for migraine...
2025-04-02 13:08:35,401 - INFO - HTTP Request: POST https://api.groq.com/openai/v1/chat/completions "HTTP/1.1 404 Not Found"
2025-04-02 13:08:35,403 - ERROR - Classification error: Error code: 404 - {'error': {'message': 'The model `llama-3-70b-8192` does not exist or you do not have access to it.', 'type': 'invalid_request_error', 'code': 'model_not_found'}}
2025-04-02 13:08:36,693 - INFO - Routed to Live Operator in 2.04 seconds
2025-04-02 13:08:36,697 - INFO - Call handled - Classification: HUMAN | Status: success
2025-04-02 13:08:51,595 - INFO - Processing query: what are your charges per day for room...
2025-04-02 13:08:52,257 - INFO - HTTP Request: POST https://api.groq.com/openai/v1/chat/completions "HTTP/1.1 404 Not Found"
2025-04-02 13:08:52,258 - ERROR - Classification error: Error code: 404 - {'error': {'message': 'The model `llama-3-70b-8192` does not exist or you do not have access to it.', 'type': 'invalid_request_error', 'code': 'model_not_found'}}
2025-04-02 13:08:54,217 - WARNING - Connection failed to Live Operator
2025-04-02 13:08:54,219 - ERROR - System error: 'response'
2025-04-02 13:09:05,155 - INFO - Processing query: what are your visisting hours...
2025-04-02 13:09:05,948 - INFO - HTTP Request: POST https://api.groq.com/openai/v1/chat/completions "HTTP/1.1 404 Not Found"
2025-04-02 13:09:05,951 - ERROR - Classification error: Error code: 404 - {'error': {'message': 'The model `llama-3-70b-8192` does not exist or you do not have access to it.', 'type': 'invalid_request_error', 'code': 'model_not_found'}}
2025-04-02 13:09:06,955 - INFO - Routed to Live Operator in 1.80 seconds
2025-04-02 13:09:06,959 - INFO - Call handled - Classification: HUMAN | Status: success
2025-04-02 13:09:32,562 - INFO - Processing query: Visiting hours...
2025-04-02 13:09:33,169 - INFO - HTTP Request: POST https://api.groq.com/openai/v1/chat/completions "HTTP/1.1 404 Not Found"
2025-04-02 13:09:33,172 - ERROR - Classification error: Error code: 404 - {'error': {'message': 'The model `llama-3-70b-8192` does not exist or you do not have access to it.', 'type': 'invalid_request_error', 'code': 'model_not_found'}}
2025-04-02 13:09:34,659 - INFO - Routed to Live Operator in 2.10 seconds
2025-04-02 13:09:34,660 - INFO - Call handled - Classification: HUMAN | Status: success
2025-04-02 13:10:58,541 - INFO - Processing query: what are your visiting hours...
2025-04-02 13:10:59,300 - INFO - HTTP Request: POST https://api.groq.com/openai/v1/chat/completions "HTTP/1.1 404 Not Found"
2025-04-02 13:10:59,302 - ERROR - Classification error: Error code: 404 - {'error': {'message': 'The model `llama-3-70b-8192` does not exist or you do not have access to it.', 'type': 'invalid_request_error', 'code': 'model_not_found'}}
2025-04-02 13:11:00,530 - INFO - Routed to Live Operator in 1.99 seconds
2025-04-02 13:11:00,531 - INFO - Call handled - Classification: HUMAN | Status: success
2025-04-02 13:11:04,118 - ERROR - System error: 
2025-04-02 13:11:10,130 - INFO - HTTP Request: POST https://api.groq.com/openai/v1/chat/completions "HTTP/1.1 404 Not Found"
2025-04-02 13:11:10,134 - ERROR - Classification error: Error code: 404 - {'error': {'message': 'The model `llama-3-70b-8192` does not exist or you do not have access to it.', 'type': 'invalid_request_error', 'code': 'model_not_found'}}
2025-04-02 13:11:10,387 - INFO - HTTP Request: POST https://api.groq.com/openai/v1/chat/completions "HTTP/1.1 404 Not Found"
2025-04-02 13:11:10,390 - ERROR - Classification error: Error code: 404 - {'error': {'message': 'The model `llama-3-70b-8192` does not exist or you do not have access to it.', 'type': 'invalid_request_error', 'code': 'model_not_found'}}
2025-04-02 13:11:10,638 - INFO - HTTP Request: POST https://api.groq.com/openai/v1/chat/completions "HTTP/1.1 404 Not Found"
2025-04-02 13:11:10,639 - ERROR - Classification error: Error code: 404 - {'error': {'message': 'The model `llama-3-70b-8192` does not exist or you do not have access to it.', 'type': 'invalid_request_error', 'code': 'model_not_found'}}
2025-04-02 13:11:10,881 - INFO - HTTP Request: POST https://api.groq.com/openai/v1/chat/completions "HTTP/1.1 404 Not Found"
2025-04-02 13:11:10,884 - ERROR - Classification error: Error code: 404 - {'error': {'message': 'The model `llama-3-70b-8192` does not exist or you do not have access to it.', 'type': 'invalid_request_error', 'code': 'model_not_found'}}
2025-04-02 13:11:11,141 - INFO - HTTP Request: POST https://api.groq.com/openai/v1/chat/completions "HTTP/1.1 404 Not Found"
2025-04-02 13:11:11,144 - ERROR - Classification error: Error code: 404 - {'error': {'message': 'The model `llama-3-70b-8192` does not exist or you do not have access to it.', 'type': 'invalid_request_error', 'code': 'model_not_found'}}
2025-04-02 13:11:17,155 - INFO - Processing query: Visiting hours...
2025-04-02 13:11:17,891 - INFO - HTTP Request: POST https://api.groq.com/openai/v1/chat/completions "HTTP/1.1 404 Not Found"
2025-04-02 13:11:17,893 - ERROR - Classification error: Error code: 404 - {'error': {'message': 'The model `llama-3-70b-8192` does not exist or you do not have access to it.', 'type': 'invalid_request_error', 'code': 'model_not_found'}}
2025-04-02 13:11:18,628 - INFO - Routed to Live Operator in 1.47 seconds
2025-04-02 13:11:18,630 - INFO - Call handled - Classification: HUMAN | Status: success
2025-04-02 13:13:07,546 - ERROR - System error: 
2025-04-02 13:13:18,814 - INFO - Processing query: What are your visiting hours...
2025-04-02 13:13:20,653 - INFO - Routed to Hospitals Policies, Rule and Regulations, Administration Guidelines in 1.84 seconds
2025-04-02 13:13:20,657 - INFO - Call handled - Classification: RAG | Status: success
2025-04-02 13:13:36,768 - INFO - Processing query: Admission policies...
2025-04-02 13:13:37,833 - INFO - HTTP Request: POST https://api.groq.com/openai/v1/chat/completions "HTTP/1.1 404 Not Found"
2025-04-02 13:13:37,836 - ERROR - Classification error: Error code: 404 - {'error': {'message': 'The model `llama-3-70b-8192` does not exist or you do not have access to it.', 'type': 'invalid_request_error', 'code': 'model_not_found'}}
2025-04-02 13:13:39,094 - INFO - Routed to Live Operator in 2.33 seconds
2025-04-02 13:13:39,098 - INFO - Call handled - Classification: HUMAN | Status: success
2025-04-02 13:13:58,827 - INFO - Processing query: care instructions for migraine...
2025-04-02 13:13:59,615 - INFO - HTTP Request: POST https://api.groq.com/openai/v1/chat/completions "HTTP/1.1 404 Not Found"
2025-04-02 13:13:59,616 - ERROR - Classification error: Error code: 404 - {'error': {'message': 'The model `llama-3-70b-8192` does not exist or you do not have access to it.', 'type': 'invalid_request_error', 'code': 'model_not_found'}}
2025-04-02 13:14:00,348 - INFO - Routed to Live Operator in 1.52 seconds
2025-04-02 13:14:00,353 - INFO - Call handled - Classification: HUMAN | Status: success
2025-04-02 13:20:21,209 - ERROR - System error: 
13:20:28.738 - HTTP Request: POST https://api.groq.com/openai/v1/chat/completions "HTTP/1.1 400 Bad Request"
13:20:28.740 - LLM timeout/error: Error code: 400 - {'error': {'message': 'The model
13:20:33.127 - HTTP Request: POST https://api.groq.com/openai/v1/chat/completions "HTTP/1.1 400 Bad Request"
13:20:33.129 - LLM timeout/error: Error code: 400 - {'error': {'message': 'The model
13:24:22.977 - HTTP Request: POST https://api.groq.com/openai/v1/chat/completions "HTTP/1.1 200 OK"
13:24:23.853 - HTTP Request: POST https://api.groq.com/openai/v1/chat/completions "HTTP/1.1 200 OK"
2025-04-02 13:29:00,035 - INFO - HTTP Request: POST https://api.groq.com/openai/v1/chat/completions "HTTP/1.1 400 Bad Request"
2025-04-02 13:29:00,039 - WARNING - LLM error: Error code: 400 - {'error': {'message': 'The model
2025-04-02 13:29:41,245 - INFO - HTTP Request: POST https://api.groq.com/openai/v1/chat/completions "HTTP/1.1 400 Bad Request"
2025-04-02 13:29:41,247 - WARNING - LLM error: Error code: 400 - {'error': {'message': 'The model
2025-04-02 13:34:09,327 - INFO - HTTP Request: POST https://api.groq.com/openai/v1/chat/completions "HTTP/1.1 400 Bad Request"
2025-04-02 13:34:09,330 - WARNING - LLM error: Error code: 400 - {'error': {'message': 'The model
2025-04-02 13:36:42,425 - INFO - HTTP Request: POST https://api.groq.com/openai/v1/chat/completions "HTTP/1.1 400 Bad Request"
2025-04-02 13:36:42,428 - WARNING - LLM error: Error code: 400 - {'error': {'message': 'The model
2025-04-02 13:38:24,145 - INFO - HTTP Request: POST https://api.groq.com/openai/v1/chat/completions "HTTP/1.1 400 Bad Request"
2025-04-02 13:38:24,148 - WARNING - LLM error: Error code: 400 - {'error': {'message': 'The model
2025-04-02 13:39:08,520 - INFO - HTTP Request: POST https://api.groq.com/openai/v1/chat/completions "HTTP/1.1 400 Bad Request"
2025-04-02 13:39:08,522 - WARNING - LLM error: Error code: 400 - {'error': {'message': 'The model
2025-04-02 13:39:31,738 - INFO - HTTP Request: POST https://api.groq.com/openai/v1/chat/completions "HTTP/1.1 400 Bad Request"
2025-04-02 13:39:31,740 - WARNING - LLM error: Error code: 400 - {'error': {'message': 'The model
2025-04-03 21:20:16,421 - ERROR - Failed to load sql agent: No module named 'prompt'
2025-04-03 21:23:12,162 - ERROR - Failed to load graph agent: [Errno 2] No such file or directory: 'D:\\agents\\graph\\main.py'
2025-04-03 21:23:12,162 - ERROR - Failed to load sql agent: [Errno 2] No such file or directory: 'D:\\agents\\sql\\main.py'
2025-04-03 21:23:12,163 - ERROR - Failed to load rag agent: [Errno 2] No such file or directory: 'D:\\agents\\rag\\main.py'
2025-04-03 22:46:29,544 - INFO - Attempting to load agent from: D:\FYP\agents\graph\main.py
2025-04-03 22:46:29,554 - ERROR - Agent file not found at D:\FYP\agents\graph\main.py
2025-04-03 22:46:29,554 - INFO - Attempting to load agent from: D:\FYP\agents\sql\main.py
2025-04-03 22:46:29,554 - ERROR - Agent file not found at D:\FYP\agents\sql\main.py
2025-04-03 22:46:29,554 - INFO - Attempting to load agent from: D:\FYP\agents\rag\main.py
2025-04-03 22:46:29,554 - ERROR - Agent file not found at D:\FYP\agents\rag\main.py
2025-04-03 22:51:23,124 - INFO - Attempting to load agent from: D:\FYP\agents\graph\main.py
2025-04-03 22:51:23,125 - ERROR - Agent file not found at D:\FYP\agents\graph\main.py
2025-04-03 22:51:23,125 - INFO - Attempting to load agent from: D:\FYP\agents\sql\main.py
2025-04-03 22:51:23,125 - ERROR - Agent file not found at D:\FYP\agents\sql\main.py
2025-04-03 22:51:23,125 - INFO - Attempting to load agent from: D:\FYP\agents\rag\main.py
2025-04-03 22:51:23,125 - ERROR - Agent file not found at D:\FYP\agents\rag\main.py
2025-04-03 22:51:23,125 - CRITICAL - Critical: GRAPH agent failed to load!
2025-04-03 22:51:23,125 - CRITICAL - Critical: SQL agent failed to load!
2025-04-03 22:51:23,126 - CRITICAL - Critical: RAG agent failed to load!
2025-04-03 22:57:21,365 - INFO - Attempting to load agent from: D:\FYP\agents\graph\main.py
2025-04-03 22:57:21,365 - ERROR - Agent file not found at D:\FYP\agents\graph\main.py
2025-04-03 22:57:21,366 - INFO - Attempting to load agent from: D:\FYP\agents\sql\main.py
2025-04-03 22:57:21,366 - ERROR - Agent file not found at D:\FYP\agents\sql\main.py
2025-04-03 22:57:21,366 - INFO - Attempting to load agent from: D:\FYP\agents\rag\main.py
2025-04-03 22:57:21,366 - ERROR - Agent file not found at D:\FYP\agents\rag\main.py
2025-04-03 22:57:21,366 - CRITICAL - Critical: GRAPH agent failed to load!
2025-04-03 22:57:21,366 - CRITICAL - Critical: SQL agent failed to load!
2025-04-03 22:57:21,366 - CRITICAL - Critical: RAG agent failed to load!
2025-04-03 22:59:21,796 - INFO - Attempting to load agent from: D:\FYP\server\agents\graph\main.py
2025-04-03 22:59:26,633 - INFO - Successfully loaded graph agent
2025-04-03 22:59:26,634 - INFO - Attempting to load agent from: D:\FYP\server\agents\sql\main.py
2025-04-03 22:59:27,531 - ERROR - Failed to load sql agent: No module named 'prompt'
Traceback (most recent call last):
  File "D:\FYP\server\router.py", line 131, in _load_agent
    spec.loader.exec_module(module)
    ~~~~~~~~~~~~~~~~~~~~~~~^^^^^^^^
  File "<frozen importlib._bootstrap_external>", line 1026, in exec_module
  File "<frozen importlib._bootstrap>", line 488, in _call_with_frames_removed
  File "D:\FYP\server\agents\sql\main.py", line 4, in <module>
    from prompt import agent_instructions
ModuleNotFoundError: No module named 'prompt'
2025-04-03 22:59:27,534 - INFO - Attempting to load agent from: D:\FYP\server\agents\rag\main.py
2025-04-03 22:59:29,952 - ERROR - rag agent missing handle_query function
2025-04-03 22:59:29,952 - INFO - GRAPH agent ready
2025-04-03 22:59:29,952 - CRITICAL - Critical: SQL agent failed to load!
2025-04-03 22:59:29,952 - CRITICAL - Critical: RAG agent failed to load!
2025-04-03 23:02:31,175 - INFO - Attempting to load agent from: D:\FYP\server\agents\graph\main.py
2025-04-03 23:02:35,502 - INFO - Successfully loaded graph agent
2025-04-03 23:02:35,502 - INFO - Attempting to load agent from: D:\FYP\server\agents\sql\main.py
2025-04-03 23:02:36,375 - ERROR - Failed to load sql agent: No module named 'prompt'
Traceback (most recent call last):
  File "D:\FYP\server\router.py", line 131, in _load_agent
    spec.loader.exec_module(module)
    ~~~~~~~~~~~~~~~~~~~~~~~^^^^^^^^
  File "<frozen importlib._bootstrap_external>", line 1026, in exec_module
  File "<frozen importlib._bootstrap>", line 488, in _call_with_frames_removed
  File "D:\FYP\server\agents\sql\main.py", line 4, in <module>
    from prompt import agent_instructions
ModuleNotFoundError: No module named 'prompt'
2025-04-03 23:02:36,378 - INFO - Attempting to load agent from: D:\FYP\server\agents\rag\main.py
2025-04-03 23:02:38,532 - ERROR - rag agent missing handle_query function
2025-04-03 23:02:38,532 - INFO - GRAPH agent ready
2025-04-03 23:02:38,532 - CRITICAL - Critical: SQL agent failed to load!
2025-04-03 23:02:38,532 - CRITICAL - Critical: RAG agent failed to load!
2025-04-03 23:03:39,798 - INFO - Attempting to load agent from: D:\FYP\server\agents\graph\main.py
2025-04-03 23:03:43,914 - INFO - Successfully loaded graph agent
2025-04-03 23:03:43,914 - INFO - Attempting to load agent from: D:\FYP\server\agents\sql\main.py
2025-04-03 23:03:44,837 - ERROR - Failed to load sql agent: No module named 'prompt'
Traceback (most recent call last):
  File "D:\FYP\server\router.py", line 131, in _load_agent
    spec.loader.exec_module(module)
    ~~~~~~~~~~~~~~~~~~~~~~~^^^^^^^^
  File "<frozen importlib._bootstrap_external>", line 1026, in exec_module
  File "<frozen importlib._bootstrap>", line 488, in _call_with_frames_removed
  File "D:\FYP\server\agents\sql\main.py", line 4, in <module>
    from prompt import agent_instructions
ModuleNotFoundError: No module named 'prompt'
2025-04-03 23:03:44,840 - INFO - Attempting to load agent from: D:\FYP\server\agents\rag\main.py
2025-04-03 23:03:47,994 - ERROR - rag agent missing handle_query function
2025-04-03 23:03:47,994 - INFO - GRAPH agent ready
2025-04-03 23:03:47,994 - CRITICAL - Critical: SQL agent failed to load!
2025-04-03 23:03:47,995 - CRITICAL - Critical: RAG agent failed to load!
2025-04-03 23:03:59,669 - INFO - HTTP Request: POST https://api.groq.com/openai/v1/chat/completions "HTTP/1.1 200 OK"
2025-04-03 23:04:00,558 - INFO - HTTP Request: POST https://api.groq.com/openai/v1/chat/completions "HTTP/1.1 200 OK"
2025-04-03 23:12:32,560 - INFO - Attempting to load agent from: D:\FYP\server\agents\graph\main.py
2025-04-03 23:12:36,848 - INFO - Successfully loaded graph agent
2025-04-03 23:12:36,848 - INFO - Attempting to load agent from: D:\FYP\server\agents\sql\main.py
2025-04-03 23:12:37,912 - ERROR - Failed to load sql agent: No module named 'prompt'
Traceback (most recent call last):
  File "D:\FYP\server\router.py", line 131, in _load_agent
    spec.loader.exec_module(module)
    ~~~~~~~~~~~~~~~~~~~~~~~^^^^^^^^
  File "<frozen importlib._bootstrap_external>", line 1026, in exec_module
  File "<frozen importlib._bootstrap>", line 488, in _call_with_frames_removed
  File "D:\FYP\server\agents\sql\main.py", line 4, in <module>
    from prompt import agent_instructions
ModuleNotFoundError: No module named 'prompt'
2025-04-03 23:12:37,915 - INFO - Attempting to load agent from: D:\FYP\server\agents\rag\main.py
2025-04-03 23:12:40,626 - ERROR - rag agent missing handle_query function
2025-04-03 23:12:40,626 - INFO - GRAPH agent ready
2025-04-03 23:12:40,626 - CRITICAL - Critical: SQL agent failed to load!
2025-04-03 23:12:40,626 - CRITICAL - Critical: RAG agent failed to load!
2025-04-03 23:15:58,912 - INFO - HTTP Request: POST https://api.groq.com/openai/v1/chat/completions "HTTP/1.1 200 OK"
2025-04-03 23:15:59,597 - INFO - HTTP Request: POST https://api.groq.com/openai/v1/chat/completions "HTTP/1.1 200 OK"
2025-04-03 23:18:07,358 - INFO - Attempting to load agent from: D:\FYP\server\agents\graph\main.py
2025-04-03 23:18:11,661 - INFO - Successfully loaded graph agent
2025-04-03 23:18:11,661 - INFO - Attempting to load agent from: D:\FYP\server\agents\sql\main.py
2025-04-03 23:18:12,552 - ERROR - Failed to load sql agent: No module named 'prompt'
Traceback (most recent call last):
  File "D:\FYP\server\router.py", line 131, in _load_agent
    spec.loader.exec_module(module)
    ~~~~~~~~~~~~~~~~~~~~~~~^^^^^^^^
  File "<frozen importlib._bootstrap_external>", line 1026, in exec_module
  File "<frozen importlib._bootstrap>", line 488, in _call_with_frames_removed
  File "D:\FYP\server\agents\sql\main.py", line 5, in <module>
    from prompt import agent_instructions
ModuleNotFoundError: No module named 'prompt'
2025-04-03 23:18:12,555 - INFO - Attempting to load agent from: D:\FYP\server\agents\rag\main.py
2025-04-03 23:18:15,571 - ERROR - rag agent missing handle_query function
2025-04-03 23:18:15,571 - INFO - GRAPH agent ready
2025-04-03 23:18:15,571 - CRITICAL - Critical: SQL agent failed to load!
2025-04-03 23:18:15,571 - CRITICAL - Critical: RAG agent failed to load!
2025-04-03 23:24:00,793 - INFO - Attempting to load agent from: D:\FYP\server\agents\graph\main.py
2025-04-03 23:24:04,909 - INFO - Successfully loaded graph agent
2025-04-03 23:24:04,909 - INFO - Attempting to load agent from: D:\FYP\server\agents\sql\main.py
2025-04-03 23:24:05,947 - ERROR - Failed to load sql agent: No module named 'prompt'
Traceback (most recent call last):
  File "D:\FYP\server\router.py", line 131, in _load_agent
    spec.loader.exec_module(module)
    ~~~~~~~~~~~~~~~~~~~~~~~^^^^^^^^
  File "<frozen importlib._bootstrap_external>", line 1026, in exec_module
  File "<frozen importlib._bootstrap>", line 488, in _call_with_frames_removed
  File "D:\FYP\server\agents\sql\main.py", line 5, in <module>
    from prompt import agent_instructions
ModuleNotFoundError: No module named 'prompt'
2025-04-03 23:24:05,951 - INFO - Attempting to load agent from: D:\FYP\server\agents\rag\main.py
2025-04-03 23:24:08,886 - ERROR - rag agent missing handle_query function
2025-04-03 23:24:08,886 - INFO - GRAPH agent ready
2025-04-03 23:24:08,886 - CRITICAL - Critical: SQL agent failed to load!
2025-04-03 23:24:08,886 - CRITICAL - Critical: RAG agent failed to load!
2025-04-04 18:20:58,152 - INFO - Attempting to load agent from: D:\FYP\server\agents\graph\main.py
2025-04-04 18:21:05,101 - ERROR - Failed to load graph agent: Could not connect to Neo4j database. Please ensure that the url is correct
Traceback (most recent call last):
  File "D:\FYP\server\env\Lib\site-packages\neo4j\_async_compat\network\_bolt_socket.py", line 409, in _connect_secure
    s.connect(resolved_address)
    ~~~~~~~~~^^^^^^^^^^^^^^^^^^
ConnectionRefusedError: [WinError 10061] No connection could be made because the target machine actively refused it

The above exception was the direct cause of the following exception:

Traceback (most recent call last):
  File "D:\FYP\server\env\Lib\site-packages\neo4j\_sync\io\_bolt_socket.py", line 328, in connect
    s = cls._connect_secure(
        resolved_address, tcp_timeout, keep_alive, ssl_context
    )
  File "D:\FYP\server\env\Lib\site-packages\neo4j\_async_compat\network\_bolt_socket.py", line 426, in _connect_secure
    raise ServiceUnavailable(
    ...<2 lines>...
    ) from error
neo4j.exceptions.ServiceUnavailable: Failed to establish connection to ResolvedIPv6Address(('::1', 7687, 0, 0)) (reason [WinError 10061] No connection could be made because the target machine actively refused it)

The above exception was the direct cause of the following exception:

Traceback (most recent call last):
  File "D:\FYP\server\env\Lib\site-packages\langchain_community\graphs\neo4j_graph.py", line 415, in __init__
    self._driver.verify_connectivity()
    ~~~~~~~~~~~~~~~~~~~~~~~~~~~~~~~~^^
  File "D:\FYP\server\env\Lib\site-packages\neo4j\_sync\driver.py", line 1082, in verify_connectivity
    self._get_server_info(session_config)
    ~~~~~~~~~~~~~~~~~~~~~^^^^^^^^^^^^^^^^
  File "D:\FYP\server\env\Lib\site-packages\neo4j\_sync\driver.py", line 1297, in _get_server_info
    return session._get_server_info()
           ~~~~~~~~~~~~~~~~~~~~~~~~^^
  File "D:\FYP\server\env\Lib\site-packages\neo4j\_sync\work\session.py", line 183, in _get_server_info
    self._connect(READ_ACCESS, liveness_check_timeout=0)
    ~~~~~~~~~~~~~^^^^^^^^^^^^^^^^^^^^^^^^^^^^^^^^^^^^^^^
  File "D:\FYP\server\env\Lib\site-packages\neo4j\_sync\work\session.py", line 136, in _connect
    super()._connect(
    ~~~~~~~~~~~~~~~~^
        access_mode, auth=self._config.auth, **acquire_kwargs
        ^^^^^^^^^^^^^^^^^^^^^^^^^^^^^^^^^^^^^^^^^^^^^^^^^^^^^
    )
    ^
  File "D:\FYP\server\env\Lib\site-packages\neo4j\_sync\work\workspace.py", line 199, in _connect
    self._connection = self._pool.acquire(**acquire_kwargs_)
                       ~~~~~~~~~~~~~~~~~~^^^^^^^^^^^^^^^^^^^
  File "D:\FYP\server\env\Lib\site-packages\neo4j\_sync\io\_pool.py", line 662, in acquire
    return self._acquire(
           ~~~~~~~~~~~~~^
        self.address, auth, deadline, liveness_check_timeout
        ^^^^^^^^^^^^^^^^^^^^^^^^^^^^^^^^^^^^^^^^^^^^^^^^^^^^
    )
    ^
  File "D:\FYP\server\env\Lib\site-packages\neo4j\_sync\io\_pool.py", line 408, in _acquire
    return connection_creator()
  File "D:\FYP\server\env\Lib\site-packages\neo4j\_sync\io\_pool.py", line 230, in connection_creator
    connection = self.opener(
        address, auth or self.pool_config.auth, deadline
    )
  File "D:\FYP\server\env\Lib\site-packages\neo4j\_sync\io\_pool.py", line 624, in opener
    return Bolt.open(
           ~~~~~~~~~^
        addr,
        ^^^^^
    ...<3 lines>...
        pool_config=pool_config,
        ^^^^^^^^^^^^^^^^^^^^^^^^
    )
    ^
  File "D:\FYP\server\env\Lib\site-packages\neo4j\_sync\io\_bolt.py", line 369, in open
    s, protocol_version, handshake, data = BoltSocket.connect(
                                           ~~~~~~~~~~~~~~~~~~^
        address,
        ^^^^^^^^
    ...<4 lines>...
        keep_alive=pool_config.keep_alive,
        ^^^^^^^^^^^^^^^^^^^^^^^^^^^^^^^^^^
    )
    ^
  File "D:\FYP\server\env\Lib\site-packages\neo4j\_sync\io\_bolt_socket.py", line 376, in connect
    raise ServiceUnavailable(
    ...<2 lines>...
    ) from errors[0]
neo4j.exceptions.ServiceUnavailable: Couldn't connect to localhost:7687 (resolved to ('[::1]:7687', '127.0.0.1:7687')):
Failed to establish connection to ResolvedIPv6Address(('::1', 7687, 0, 0)) (reason [WinError 10061] No connection could be made because the target machine actively refused it)
Failed to establish connection to ResolvedIPv4Address(('127.0.0.1', 7687)) (reason [WinError 10061] No connection could be made because the target machine actively refused it)

During handling of the above exception, another exception occurred:

Traceback (most recent call last):
  File "D:\FYP\server\router.py", line 131, in _load_agent
    spec.loader.exec_module(module)
    ~~~~~~~~~~~~~~~~~~~~~~~^^^^^^^^
  File "<frozen importlib._bootstrap_external>", line 1026, in exec_module
  File "<frozen importlib._bootstrap>", line 488, in _call_with_frames_removed
  File "D:\FYP\server\agents\graph\main.py", line 14, in <module>
    graph = Neo4jGraph(
        url=os.getenv("NEO4J_URI"),
    ...<2 lines>...
        database="medicalrag"
    )
  File "D:\FYP\server\env\Lib\site-packages\langchain_core\_api\deprecation.py", line 214, in warn_if_direct_instance
    return wrapped(self, *args, **kwargs)
  File "D:\FYP\server\env\Lib\site-packages\langchain_community\graphs\neo4j_graph.py", line 417, in __init__
    raise ValueError(
    ...<2 lines>...
    )
ValueError: Could not connect to Neo4j database. Please ensure that the url is correct
2025-04-04 18:21:05,449 - INFO - Attempting to load agent from: D:\FYP\server\agents\sql\main.py
2025-04-04 18:21:06,893 - ERROR - Failed to load sql agent: No module named 'prompt'
Traceback (most recent call last):
  File "D:\FYP\server\router.py", line 131, in _load_agent
    spec.loader.exec_module(module)
    ~~~~~~~~~~~~~~~~~~~~~~~^^^^^^^^
  File "<frozen importlib._bootstrap_external>", line 1026, in exec_module
  File "<frozen importlib._bootstrap>", line 488, in _call_with_frames_removed
  File "D:\FYP\server\agents\sql\main.py", line 5, in <module>
    from prompt import agent_instructions
ModuleNotFoundError: No module named 'prompt'
2025-04-04 18:21:06,895 - INFO - Attempting to load agent from: D:\FYP\server\agents\rag\main.py
2025-04-04 18:21:10,939 - ERROR - rag agent missing handle_query function
2025-04-04 18:21:10,940 - CRITICAL - Critical: GRAPH agent failed to load!
2025-04-04 18:21:10,940 - CRITICAL - Critical: SQL agent failed to load!
2025-04-04 18:21:10,940 - CRITICAL - Critical: RAG agent failed to load!
2025-04-04 18:37:28,413 - INFO - Attempting to load agent from: D:\FYP\server\agents\graph\main.py
2025-04-04 18:37:33,595 - ERROR - Failed to load graph agent: Could not connect to Neo4j database. Please ensure that the url is correct
Traceback (most recent call last):
  File "D:\FYP\server\env\Lib\site-packages\neo4j\_async_compat\network\_bolt_socket.py", line 409, in _connect_secure
    s.connect(resolved_address)
    ~~~~~~~~~^^^^^^^^^^^^^^^^^^
ConnectionRefusedError: [WinError 10061] No connection could be made because the target machine actively refused it

The above exception was the direct cause of the following exception:

Traceback (most recent call last):
  File "D:\FYP\server\env\Lib\site-packages\neo4j\_sync\io\_bolt_socket.py", line 328, in connect
    s = cls._connect_secure(
        resolved_address, tcp_timeout, keep_alive, ssl_context
    )
  File "D:\FYP\server\env\Lib\site-packages\neo4j\_async_compat\network\_bolt_socket.py", line 426, in _connect_secure
    raise ServiceUnavailable(
    ...<2 lines>...
    ) from error
neo4j.exceptions.ServiceUnavailable: Failed to establish connection to ResolvedIPv6Address(('::1', 7687, 0, 0)) (reason [WinError 10061] No connection could be made because the target machine actively refused it)

The above exception was the direct cause of the following exception:

Traceback (most recent call last):
  File "D:\FYP\server\env\Lib\site-packages\langchain_community\graphs\neo4j_graph.py", line 415, in __init__
    self._driver.verify_connectivity()
    ~~~~~~~~~~~~~~~~~~~~~~~~~~~~~~~~^^
  File "D:\FYP\server\env\Lib\site-packages\neo4j\_sync\driver.py", line 1082, in verify_connectivity
    self._get_server_info(session_config)
    ~~~~~~~~~~~~~~~~~~~~~^^^^^^^^^^^^^^^^
  File "D:\FYP\server\env\Lib\site-packages\neo4j\_sync\driver.py", line 1297, in _get_server_info
    return session._get_server_info()
           ~~~~~~~~~~~~~~~~~~~~~~~~^^
  File "D:\FYP\server\env\Lib\site-packages\neo4j\_sync\work\session.py", line 183, in _get_server_info
    self._connect(READ_ACCESS, liveness_check_timeout=0)
    ~~~~~~~~~~~~~^^^^^^^^^^^^^^^^^^^^^^^^^^^^^^^^^^^^^^^
  File "D:\FYP\server\env\Lib\site-packages\neo4j\_sync\work\session.py", line 136, in _connect
    super()._connect(
    ~~~~~~~~~~~~~~~~^
        access_mode, auth=self._config.auth, **acquire_kwargs
        ^^^^^^^^^^^^^^^^^^^^^^^^^^^^^^^^^^^^^^^^^^^^^^^^^^^^^
    )
    ^
  File "D:\FYP\server\env\Lib\site-packages\neo4j\_sync\work\workspace.py", line 199, in _connect
    self._connection = self._pool.acquire(**acquire_kwargs_)
                       ~~~~~~~~~~~~~~~~~~^^^^^^^^^^^^^^^^^^^
  File "D:\FYP\server\env\Lib\site-packages\neo4j\_sync\io\_pool.py", line 662, in acquire
    return self._acquire(
           ~~~~~~~~~~~~~^
        self.address, auth, deadline, liveness_check_timeout
        ^^^^^^^^^^^^^^^^^^^^^^^^^^^^^^^^^^^^^^^^^^^^^^^^^^^^
    )
    ^
  File "D:\FYP\server\env\Lib\site-packages\neo4j\_sync\io\_pool.py", line 408, in _acquire
    return connection_creator()
  File "D:\FYP\server\env\Lib\site-packages\neo4j\_sync\io\_pool.py", line 230, in connection_creator
    connection = self.opener(
        address, auth or self.pool_config.auth, deadline
    )
  File "D:\FYP\server\env\Lib\site-packages\neo4j\_sync\io\_pool.py", line 624, in opener
    return Bolt.open(
           ~~~~~~~~~^
        addr,
        ^^^^^
    ...<3 lines>...
        pool_config=pool_config,
        ^^^^^^^^^^^^^^^^^^^^^^^^
    )
    ^
  File "D:\FYP\server\env\Lib\site-packages\neo4j\_sync\io\_bolt.py", line 369, in open
    s, protocol_version, handshake, data = BoltSocket.connect(
                                           ~~~~~~~~~~~~~~~~~~^
        address,
        ^^^^^^^^
    ...<4 lines>...
        keep_alive=pool_config.keep_alive,
        ^^^^^^^^^^^^^^^^^^^^^^^^^^^^^^^^^^
    )
    ^
  File "D:\FYP\server\env\Lib\site-packages\neo4j\_sync\io\_bolt_socket.py", line 376, in connect
    raise ServiceUnavailable(
    ...<2 lines>...
    ) from errors[0]
neo4j.exceptions.ServiceUnavailable: Couldn't connect to localhost:7687 (resolved to ('[::1]:7687', '127.0.0.1:7687')):
Failed to establish connection to ResolvedIPv6Address(('::1', 7687, 0, 0)) (reason [WinError 10061] No connection could be made because the target machine actively refused it)
Failed to establish connection to ResolvedIPv4Address(('127.0.0.1', 7687)) (reason [WinError 10061] No connection could be made because the target machine actively refused it)

During handling of the above exception, another exception occurred:

Traceback (most recent call last):
  File "D:\FYP\server\router.py", line 131, in _load_agent
    spec.loader.exec_module(module)
    ~~~~~~~~~~~~~~~~~~~~~~~^^^^^^^^
  File "<frozen importlib._bootstrap_external>", line 1026, in exec_module
  File "<frozen importlib._bootstrap>", line 488, in _call_with_frames_removed
  File "D:\FYP\server\agents\graph\main.py", line 14, in <module>
    graph = Neo4jGraph(
        url=os.getenv("NEO4J_URI"),
    ...<2 lines>...
        database="medicalrag"
    )
  File "D:\FYP\server\env\Lib\site-packages\langchain_core\_api\deprecation.py", line 214, in warn_if_direct_instance
    return wrapped(self, *args, **kwargs)
  File "D:\FYP\server\env\Lib\site-packages\langchain_community\graphs\neo4j_graph.py", line 417, in __init__
    raise ValueError(
    ...<2 lines>...
    )
ValueError: Could not connect to Neo4j database. Please ensure that the url is correct
2025-04-04 18:37:33,636 - INFO - Attempting to load agent from: D:\FYP\server\agents\sql\main.py
2025-04-04 18:37:34,560 - ERROR - Failed to load sql agent: No module named 'prompt'
Traceback (most recent call last):
  File "D:\FYP\server\router.py", line 131, in _load_agent
    spec.loader.exec_module(module)
    ~~~~~~~~~~~~~~~~~~~~~~~^^^^^^^^
  File "<frozen importlib._bootstrap_external>", line 1026, in exec_module
  File "<frozen importlib._bootstrap>", line 488, in _call_with_frames_removed
  File "D:\FYP\server\agents\sql\main.py", line 5, in <module>
    from prompt import agent_instructions
ModuleNotFoundError: No module named 'prompt'
2025-04-04 18:37:34,563 - INFO - Attempting to load agent from: D:\FYP\server\agents\rag\main.py
2025-04-04 18:37:36,910 - ERROR - rag agent missing handle_query function
2025-04-04 18:37:36,911 - CRITICAL - Critical: GRAPH agent failed to load!
2025-04-04 18:37:36,911 - CRITICAL - Critical: SQL agent failed to load!
2025-04-04 18:37:36,911 - CRITICAL - Critical: RAG agent failed to load!
2025-04-04 18:39:44,335 - INFO - Attempting to load agent from: D:\FYP\server\agents\graph\main.py
2025-04-04 18:39:49,482 - ERROR - Failed to load graph agent: Could not connect to Neo4j database. Please ensure that the url is correct
Traceback (most recent call last):
  File "D:\FYP\server\env\Lib\site-packages\neo4j\_async_compat\network\_bolt_socket.py", line 409, in _connect_secure
    s.connect(resolved_address)
    ~~~~~~~~~^^^^^^^^^^^^^^^^^^
ConnectionRefusedError: [WinError 10061] No connection could be made because the target machine actively refused it

The above exception was the direct cause of the following exception:

Traceback (most recent call last):
  File "D:\FYP\server\env\Lib\site-packages\neo4j\_sync\io\_bolt_socket.py", line 328, in connect
    s = cls._connect_secure(
        resolved_address, tcp_timeout, keep_alive, ssl_context
    )
  File "D:\FYP\server\env\Lib\site-packages\neo4j\_async_compat\network\_bolt_socket.py", line 426, in _connect_secure
    raise ServiceUnavailable(
    ...<2 lines>...
    ) from error
neo4j.exceptions.ServiceUnavailable: Failed to establish connection to ResolvedIPv6Address(('::1', 7687, 0, 0)) (reason [WinError 10061] No connection could be made because the target machine actively refused it)

The above exception was the direct cause of the following exception:

Traceback (most recent call last):
  File "D:\FYP\server\env\Lib\site-packages\langchain_community\graphs\neo4j_graph.py", line 415, in __init__
    self._driver.verify_connectivity()
    ~~~~~~~~~~~~~~~~~~~~~~~~~~~~~~~~^^
  File "D:\FYP\server\env\Lib\site-packages\neo4j\_sync\driver.py", line 1082, in verify_connectivity
    self._get_server_info(session_config)
    ~~~~~~~~~~~~~~~~~~~~~^^^^^^^^^^^^^^^^
  File "D:\FYP\server\env\Lib\site-packages\neo4j\_sync\driver.py", line 1297, in _get_server_info
    return session._get_server_info()
           ~~~~~~~~~~~~~~~~~~~~~~~~^^
  File "D:\FYP\server\env\Lib\site-packages\neo4j\_sync\work\session.py", line 183, in _get_server_info
    self._connect(READ_ACCESS, liveness_check_timeout=0)
    ~~~~~~~~~~~~~^^^^^^^^^^^^^^^^^^^^^^^^^^^^^^^^^^^^^^^
  File "D:\FYP\server\env\Lib\site-packages\neo4j\_sync\work\session.py", line 136, in _connect
    super()._connect(
    ~~~~~~~~~~~~~~~~^
        access_mode, auth=self._config.auth, **acquire_kwargs
        ^^^^^^^^^^^^^^^^^^^^^^^^^^^^^^^^^^^^^^^^^^^^^^^^^^^^^
    )
    ^
  File "D:\FYP\server\env\Lib\site-packages\neo4j\_sync\work\workspace.py", line 199, in _connect
    self._connection = self._pool.acquire(**acquire_kwargs_)
                       ~~~~~~~~~~~~~~~~~~^^^^^^^^^^^^^^^^^^^
  File "D:\FYP\server\env\Lib\site-packages\neo4j\_sync\io\_pool.py", line 662, in acquire
    return self._acquire(
           ~~~~~~~~~~~~~^
        self.address, auth, deadline, liveness_check_timeout
        ^^^^^^^^^^^^^^^^^^^^^^^^^^^^^^^^^^^^^^^^^^^^^^^^^^^^
    )
    ^
  File "D:\FYP\server\env\Lib\site-packages\neo4j\_sync\io\_pool.py", line 408, in _acquire
    return connection_creator()
  File "D:\FYP\server\env\Lib\site-packages\neo4j\_sync\io\_pool.py", line 230, in connection_creator
    connection = self.opener(
        address, auth or self.pool_config.auth, deadline
    )
  File "D:\FYP\server\env\Lib\site-packages\neo4j\_sync\io\_pool.py", line 624, in opener
    return Bolt.open(
           ~~~~~~~~~^
        addr,
        ^^^^^
    ...<3 lines>...
        pool_config=pool_config,
        ^^^^^^^^^^^^^^^^^^^^^^^^
    )
    ^
  File "D:\FYP\server\env\Lib\site-packages\neo4j\_sync\io\_bolt.py", line 369, in open
    s, protocol_version, handshake, data = BoltSocket.connect(
                                           ~~~~~~~~~~~~~~~~~~^
        address,
        ^^^^^^^^
    ...<4 lines>...
        keep_alive=pool_config.keep_alive,
        ^^^^^^^^^^^^^^^^^^^^^^^^^^^^^^^^^^
    )
    ^
  File "D:\FYP\server\env\Lib\site-packages\neo4j\_sync\io\_bolt_socket.py", line 376, in connect
    raise ServiceUnavailable(
    ...<2 lines>...
    ) from errors[0]
neo4j.exceptions.ServiceUnavailable: Couldn't connect to localhost:7687 (resolved to ('[::1]:7687', '127.0.0.1:7687')):
Failed to establish connection to ResolvedIPv6Address(('::1', 7687, 0, 0)) (reason [WinError 10061] No connection could be made because the target machine actively refused it)
Failed to establish connection to ResolvedIPv4Address(('127.0.0.1', 7687)) (reason [WinError 10061] No connection could be made because the target machine actively refused it)

During handling of the above exception, another exception occurred:

Traceback (most recent call last):
  File "D:\FYP\server\router.py", line 131, in _load_agent
    spec.loader.exec_module(module)
    ~~~~~~~~~~~~~~~~~~~~~~~^^^^^^^^
  File "<frozen importlib._bootstrap_external>", line 1026, in exec_module
  File "<frozen importlib._bootstrap>", line 488, in _call_with_frames_removed
  File "D:\FYP\server\agents\graph\main.py", line 14, in <module>
    graph = Neo4jGraph(
        url=os.getenv("NEO4J_URI"),
    ...<2 lines>...
        database="medicalrag"
    )
  File "D:\FYP\server\env\Lib\site-packages\langchain_core\_api\deprecation.py", line 214, in warn_if_direct_instance
    return wrapped(self, *args, **kwargs)
  File "D:\FYP\server\env\Lib\site-packages\langchain_community\graphs\neo4j_graph.py", line 417, in __init__
    raise ValueError(
    ...<2 lines>...
    )
ValueError: Could not connect to Neo4j database. Please ensure that the url is correct
2025-04-04 18:39:49,515 - INFO - Attempting to load agent from: D:\FYP\server\agents\sql\main.py
2025-04-04 18:39:50,257 - ERROR - Failed to load sql agent: No module named 'prompt'
Traceback (most recent call last):
  File "D:\FYP\server\router.py", line 131, in _load_agent
    spec.loader.exec_module(module)
    ~~~~~~~~~~~~~~~~~~~~~~~^^^^^^^^
  File "<frozen importlib._bootstrap_external>", line 1026, in exec_module
  File "<frozen importlib._bootstrap>", line 488, in _call_with_frames_removed
  File "D:\FYP\server\agents\sql\main.py", line 5, in <module>
    from prompt import agent_instructions
ModuleNotFoundError: No module named 'prompt'
2025-04-04 18:39:50,258 - INFO - Attempting to load agent from: D:\FYP\server\agents\rag\main.py
2025-04-04 18:39:52,978 - INFO - Successfully loaded rag agent
2025-04-04 18:39:52,979 - CRITICAL - Critical: GRAPH agent failed to load!
2025-04-04 18:39:52,979 - CRITICAL - Critical: SQL agent failed to load!
2025-04-04 18:39:52,979 - INFO - RAG agent ready
2025-04-04 18:40:15,128 - INFO - HTTP Request: POST https://api.cohere.com/v1/embed "HTTP/1.1 200 OK"
2025-04-04 18:40:15,490 - INFO - HTTP Request: POST https://api.cohere.com/v1/embed "HTTP/1.1 200 OK"
2025-04-04 18:40:15,836 - INFO - HTTP Request: POST https://api.cohere.com/v1/embed "HTTP/1.1 200 OK"
2025-04-04 18:40:16,185 - INFO - HTTP Request: POST https://api.cohere.com/v1/embed "HTTP/1.1 200 OK"
2025-04-04 18:40:16,541 - INFO - HTTP Request: POST https://api.cohere.com/v1/embed "HTTP/1.1 200 OK"
2025-04-04 18:40:17,027 - INFO - HTTP Request: POST https://api.cohere.com/v1/embed "HTTP/1.1 200 OK"
2025-04-04 18:40:17,383 - INFO - HTTP Request: POST https://api.cohere.com/v1/embed "HTTP/1.1 200 OK"
2025-04-04 18:40:17,710 - INFO - HTTP Request: POST https://api.cohere.com/v1/embed "HTTP/1.1 200 OK"
2025-04-04 18:40:20,118 - INFO - HTTP Request: POST https://adxmtyjibwipeivrxcil.supabase.co/rest/v1/rpc/search_hospital_documents "HTTP/2 200 OK"
2025-04-04 18:40:20,919 - INFO - HTTP Request: POST https://api.groq.com/openai/v1/chat/completions "HTTP/1.1 200 OK"
2025-04-04 19:15:22,295 - INFO - Attempting to load agent from: D:\FYP\server\agents\graph\main.py
2025-04-04 19:15:27,676 - ERROR - Failed to load graph agent: Could not connect to Neo4j database. Please ensure that the url is correct
Traceback (most recent call last):
  File "D:\FYP\server\env\Lib\site-packages\neo4j\_async_compat\network\_bolt_socket.py", line 409, in _connect_secure
    s.connect(resolved_address)
    ~~~~~~~~~^^^^^^^^^^^^^^^^^^
ConnectionRefusedError: [WinError 10061] No connection could be made because the target machine actively refused it

The above exception was the direct cause of the following exception:

Traceback (most recent call last):
  File "D:\FYP\server\env\Lib\site-packages\neo4j\_sync\io\_bolt_socket.py", line 328, in connect
    s = cls._connect_secure(
        resolved_address, tcp_timeout, keep_alive, ssl_context
    )
  File "D:\FYP\server\env\Lib\site-packages\neo4j\_async_compat\network\_bolt_socket.py", line 426, in _connect_secure
    raise ServiceUnavailable(
    ...<2 lines>...
    ) from error
neo4j.exceptions.ServiceUnavailable: Failed to establish connection to ResolvedIPv6Address(('::1', 7687, 0, 0)) (reason [WinError 10061] No connection could be made because the target machine actively refused it)

The above exception was the direct cause of the following exception:

Traceback (most recent call last):
  File "D:\FYP\server\env\Lib\site-packages\langchain_community\graphs\neo4j_graph.py", line 415, in __init__
    self._driver.verify_connectivity()
    ~~~~~~~~~~~~~~~~~~~~~~~~~~~~~~~~^^
  File "D:\FYP\server\env\Lib\site-packages\neo4j\_sync\driver.py", line 1082, in verify_connectivity
    self._get_server_info(session_config)
    ~~~~~~~~~~~~~~~~~~~~~^^^^^^^^^^^^^^^^
  File "D:\FYP\server\env\Lib\site-packages\neo4j\_sync\driver.py", line 1297, in _get_server_info
    return session._get_server_info()
           ~~~~~~~~~~~~~~~~~~~~~~~~^^
  File "D:\FYP\server\env\Lib\site-packages\neo4j\_sync\work\session.py", line 183, in _get_server_info
    self._connect(READ_ACCESS, liveness_check_timeout=0)
    ~~~~~~~~~~~~~^^^^^^^^^^^^^^^^^^^^^^^^^^^^^^^^^^^^^^^
  File "D:\FYP\server\env\Lib\site-packages\neo4j\_sync\work\session.py", line 136, in _connect
    super()._connect(
    ~~~~~~~~~~~~~~~~^
        access_mode, auth=self._config.auth, **acquire_kwargs
        ^^^^^^^^^^^^^^^^^^^^^^^^^^^^^^^^^^^^^^^^^^^^^^^^^^^^^
    )
    ^
  File "D:\FYP\server\env\Lib\site-packages\neo4j\_sync\work\workspace.py", line 199, in _connect
    self._connection = self._pool.acquire(**acquire_kwargs_)
                       ~~~~~~~~~~~~~~~~~~^^^^^^^^^^^^^^^^^^^
  File "D:\FYP\server\env\Lib\site-packages\neo4j\_sync\io\_pool.py", line 662, in acquire
    return self._acquire(
           ~~~~~~~~~~~~~^
        self.address, auth, deadline, liveness_check_timeout
        ^^^^^^^^^^^^^^^^^^^^^^^^^^^^^^^^^^^^^^^^^^^^^^^^^^^^
    )
    ^
  File "D:\FYP\server\env\Lib\site-packages\neo4j\_sync\io\_pool.py", line 408, in _acquire
    return connection_creator()
  File "D:\FYP\server\env\Lib\site-packages\neo4j\_sync\io\_pool.py", line 230, in connection_creator
    connection = self.opener(
        address, auth or self.pool_config.auth, deadline
    )
  File "D:\FYP\server\env\Lib\site-packages\neo4j\_sync\io\_pool.py", line 624, in opener
    return Bolt.open(
           ~~~~~~~~~^
        addr,
        ^^^^^
    ...<3 lines>...
        pool_config=pool_config,
        ^^^^^^^^^^^^^^^^^^^^^^^^
    )
    ^
  File "D:\FYP\server\env\Lib\site-packages\neo4j\_sync\io\_bolt.py", line 369, in open
    s, protocol_version, handshake, data = BoltSocket.connect(
                                           ~~~~~~~~~~~~~~~~~~^
        address,
        ^^^^^^^^
    ...<4 lines>...
        keep_alive=pool_config.keep_alive,
        ^^^^^^^^^^^^^^^^^^^^^^^^^^^^^^^^^^
    )
    ^
  File "D:\FYP\server\env\Lib\site-packages\neo4j\_sync\io\_bolt_socket.py", line 376, in connect
    raise ServiceUnavailable(
    ...<2 lines>...
    ) from errors[0]
neo4j.exceptions.ServiceUnavailable: Couldn't connect to localhost:7687 (resolved to ('[::1]:7687', '127.0.0.1:7687')):
Failed to establish connection to ResolvedIPv6Address(('::1', 7687, 0, 0)) (reason [WinError 10061] No connection could be made because the target machine actively refused it)
Failed to establish connection to ResolvedIPv4Address(('127.0.0.1', 7687)) (reason [WinError 10061] No connection could be made because the target machine actively refused it)

During handling of the above exception, another exception occurred:

Traceback (most recent call last):
  File "D:\FYP\server\router.py", line 131, in _load_agent
    spec.loader.exec_module(module)
    ~~~~~~~~~~~~~~~~~~~~~~~^^^^^^^^
  File "<frozen importlib._bootstrap_external>", line 1026, in exec_module
  File "<frozen importlib._bootstrap>", line 488, in _call_with_frames_removed
  File "D:\FYP\server\agents\graph\main.py", line 14, in <module>
    graph = Neo4jGraph(
        url=os.getenv("NEO4J_URI"),
    ...<2 lines>...
        database="medicalrag"
    )
  File "D:\FYP\server\env\Lib\site-packages\langchain_core\_api\deprecation.py", line 214, in warn_if_direct_instance
    return wrapped(self, *args, **kwargs)
  File "D:\FYP\server\env\Lib\site-packages\langchain_community\graphs\neo4j_graph.py", line 417, in __init__
    raise ValueError(
    ...<2 lines>...
    )
ValueError: Could not connect to Neo4j database. Please ensure that the url is correct
2025-04-04 19:15:27,710 - INFO - Attempting to load agent from: D:\FYP\server\agents\sql\main.py
2025-04-04 19:15:28,502 - ERROR - Failed to load sql agent: No module named 'prompt'
Traceback (most recent call last):
  File "D:\FYP\server\router.py", line 131, in _load_agent
    spec.loader.exec_module(module)
    ~~~~~~~~~~~~~~~~~~~~~~~^^^^^^^^
  File "<frozen importlib._bootstrap_external>", line 1026, in exec_module
  File "<frozen importlib._bootstrap>", line 488, in _call_with_frames_removed
  File "D:\FYP\server\agents\sql\main.py", line 5, in <module>
    from prompt import agent_instructions
ModuleNotFoundError: No module named 'prompt'
2025-04-04 19:15:28,504 - INFO - Attempting to load agent from: D:\FYP\server\agents\rag\main.py
2025-04-04 19:15:30,774 - INFO - Successfully loaded rag agent
2025-04-04 19:15:30,774 - CRITICAL - Critical: GRAPH agent failed to load!
2025-04-04 19:15:30,774 - CRITICAL - Critical: SQL agent failed to load!
2025-04-04 19:15:30,774 - INFO - RAG agent ready
2025-04-04 19:19:41,243 - ERROR - Failed to load graph agent: Could not connect to Neo4j database. Please ensure that the url is correct
Traceback (most recent call last):
  File "D:\FYP\server\env\Lib\site-packages\neo4j\_async_compat\network\_bolt_socket.py", line 409, in _connect_secure
    s.connect(resolved_address)
    ~~~~~~~~~^^^^^^^^^^^^^^^^^^
ConnectionRefusedError: [WinError 10061] No connection could be made because the target machine actively refused it

The above exception was the direct cause of the following exception:

Traceback (most recent call last):
  File "D:\FYP\server\env\Lib\site-packages\neo4j\_sync\io\_bolt_socket.py", line 328, in connect
    s = cls._connect_secure(
        resolved_address, tcp_timeout, keep_alive, ssl_context
    )
  File "D:\FYP\server\env\Lib\site-packages\neo4j\_async_compat\network\_bolt_socket.py", line 426, in _connect_secure
    raise ServiceUnavailable(
    ...<2 lines>...
    ) from error
neo4j.exceptions.ServiceUnavailable: Failed to establish connection to ResolvedIPv6Address(('::1', 7687, 0, 0)) (reason [WinError 10061] No connection could be made because the target machine actively refused it)

The above exception was the direct cause of the following exception:

Traceback (most recent call last):
  File "D:\FYP\server\env\Lib\site-packages\langchain_community\graphs\neo4j_graph.py", line 415, in __init__
    self._driver.verify_connectivity()
    ~~~~~~~~~~~~~~~~~~~~~~~~~~~~~~~~^^
  File "D:\FYP\server\env\Lib\site-packages\neo4j\_sync\driver.py", line 1082, in verify_connectivity
    self._get_server_info(session_config)
    ~~~~~~~~~~~~~~~~~~~~~^^^^^^^^^^^^^^^^
  File "D:\FYP\server\env\Lib\site-packages\neo4j\_sync\driver.py", line 1297, in _get_server_info
    return session._get_server_info()
           ~~~~~~~~~~~~~~~~~~~~~~~~^^
  File "D:\FYP\server\env\Lib\site-packages\neo4j\_sync\work\session.py", line 183, in _get_server_info
    self._connect(READ_ACCESS, liveness_check_timeout=0)
    ~~~~~~~~~~~~~^^^^^^^^^^^^^^^^^^^^^^^^^^^^^^^^^^^^^^^
  File "D:\FYP\server\env\Lib\site-packages\neo4j\_sync\work\session.py", line 136, in _connect
    super()._connect(
    ~~~~~~~~~~~~~~~~^
        access_mode, auth=self._config.auth, **acquire_kwargs
        ^^^^^^^^^^^^^^^^^^^^^^^^^^^^^^^^^^^^^^^^^^^^^^^^^^^^^
    )
    ^
  File "D:\FYP\server\env\Lib\site-packages\neo4j\_sync\work\workspace.py", line 199, in _connect
    self._connection = self._pool.acquire(**acquire_kwargs_)
                       ~~~~~~~~~~~~~~~~~~^^^^^^^^^^^^^^^^^^^
  File "D:\FYP\server\env\Lib\site-packages\neo4j\_sync\io\_pool.py", line 662, in acquire
    return self._acquire(
           ~~~~~~~~~~~~~^
        self.address, auth, deadline, liveness_check_timeout
        ^^^^^^^^^^^^^^^^^^^^^^^^^^^^^^^^^^^^^^^^^^^^^^^^^^^^
    )
    ^
  File "D:\FYP\server\env\Lib\site-packages\neo4j\_sync\io\_pool.py", line 408, in _acquire
    return connection_creator()
  File "D:\FYP\server\env\Lib\site-packages\neo4j\_sync\io\_pool.py", line 230, in connection_creator
    connection = self.opener(
        address, auth or self.pool_config.auth, deadline
    )
  File "D:\FYP\server\env\Lib\site-packages\neo4j\_sync\io\_pool.py", line 624, in opener
    return Bolt.open(
           ~~~~~~~~~^
        addr,
        ^^^^^
    ...<3 lines>...
        pool_config=pool_config,
        ^^^^^^^^^^^^^^^^^^^^^^^^
    )
    ^
  File "D:\FYP\server\env\Lib\site-packages\neo4j\_sync\io\_bolt.py", line 369, in open
    s, protocol_version, handshake, data = BoltSocket.connect(
                                           ~~~~~~~~~~~~~~~~~~^
        address,
        ^^^^^^^^
    ...<4 lines>...
        keep_alive=pool_config.keep_alive,
        ^^^^^^^^^^^^^^^^^^^^^^^^^^^^^^^^^^
    )
    ^
  File "D:\FYP\server\env\Lib\site-packages\neo4j\_sync\io\_bolt_socket.py", line 376, in connect
    raise ServiceUnavailable(
    ...<2 lines>...
    ) from errors[0]
neo4j.exceptions.ServiceUnavailable: Couldn't connect to localhost:7687 (resolved to ('[::1]:7687', '127.0.0.1:7687')):
Failed to establish connection to ResolvedIPv6Address(('::1', 7687, 0, 0)) (reason [WinError 10061] No connection could be made because the target machine actively refused it)
Failed to establish connection to ResolvedIPv4Address(('127.0.0.1', 7687)) (reason [WinError 10061] No connection could be made because the target machine actively refused it)

During handling of the above exception, another exception occurred:

Traceback (most recent call last):
  File "D:\FYP\server\router.py", line 131, in _load_agent
    spec.loader.exec_module(module)
    ~~~~~~~~~~~~~~~~~~~~~~~^^^^^^^^
  File "<frozen importlib._bootstrap_external>", line 1026, in exec_module
  File "<frozen importlib._bootstrap>", line 488, in _call_with_frames_removed
  File "D:\FYP\server\agents\graph\main.py", line 14, in <module>
    graph = Neo4jGraph(
        url=os.getenv("NEO4J_URI"),
    ...<2 lines>...
        database="medicalrag"
    )
  File "D:\FYP\server\env\Lib\site-packages\langchain_core\_api\deprecation.py", line 214, in warn_if_direct_instance
    return wrapped(self, *args, **kwargs)
  File "D:\FYP\server\env\Lib\site-packages\langchain_community\graphs\neo4j_graph.py", line 417, in __init__
    raise ValueError(
    ...<2 lines>...
    )
ValueError: Could not connect to Neo4j database. Please ensure that the url is correct
2025-04-04 19:19:42,091 - ERROR - Failed to load sql agent: No module named 'prompt'
Traceback (most recent call last):
  File "D:\FYP\server\router.py", line 131, in _load_agent
    spec.loader.exec_module(module)
    ~~~~~~~~~~~~~~~~~~~~~~~^^^^^^^^
  File "<frozen importlib._bootstrap_external>", line 1026, in exec_module
  File "<frozen importlib._bootstrap>", line 488, in _call_with_frames_removed
  File "D:\FYP\server\agents\sql\main.py", line 5, in <module>
    from prompt import agent_instructions
ModuleNotFoundError: No module named 'prompt'
2025-04-04 19:19:44,372 - INFO - Successfully loaded rag agent
2025-04-04 19:19:44,373 - INFO - RAG agent ready
2025-04-04 19:22:42,286 - INFO - RAG agent ready
2025-04-04 20:36:52,256 - INFO - RAG agent ready
2025-04-04 20:37:41,870 - INFO - RAG agent ready
2025-04-04 20:40:27,318 - INFO - RAG agent ready
2025-04-04 20:42:50,519 - INFO - RAG agent ready
2025-04-04 20:47:16,963 - INFO - RAG agent ready
2025-04-04 20:51:25,619 - INFO - RAG agent ready
2025-04-04 20:52:12,626 - INFO - RAG agent ready
2025-04-04 20:53:16,999 - INFO - RAG agent ready
2025-04-04 20:55:03,320 - INFO - SQL agent ready
2025-04-04 20:55:03,320 - INFO - RAG agent ready
2025-04-04 20:55:19,238 - INFO - HTTP Request: POST https://api.groq.com/openai/v1/chat/completions "HTTP/1.1 400 Bad Request"
2025-04-04 21:13:47,332 - INFO - SQL agent ready
2025-04-04 21:13:47,332 - INFO - RAG agent ready
2025-04-04 21:13:57,988 - INFO - HTTP Request: POST https://api.groq.com/openai/v1/chat/completions "HTTP/1.1 200 OK"
2025-04-04 21:13:58,911 - INFO - HTTP Request: POST https://api.groq.com/openai/v1/chat/completions "HTTP/1.1 200 OK"
2025-04-04 21:14:00,626 - INFO - HTTP Request: GET https://adxmtyjibwipeivrxcil.supabase.co/rest/v1/doctors?select=name "HTTP/2 200 OK"
2025-04-04 21:14:10,553 - INFO - HTTP Request: POST https://api.groq.com/openai/v1/chat/completions "HTTP/1.1 200 OK"
2025-04-04 21:14:11,302 - INFO - HTTP Request: GET https://adxmtyjibwipeivrxcil.supabase.co/rest/v1/doctors?select=name "HTTP/2 200 OK"
2025-04-04 21:14:11,916 - INFO - HTTP Request: GET https://adxmtyjibwipeivrxcil.supabase.co/rest/v1/doctors?select=%2A&name=eq.Angela+Webb "HTTP/2 200 OK"
2025-04-04 21:14:12,908 - INFO - HTTP Request: POST https://api.groq.com/openai/v1/chat/completions "HTTP/1.1 200 OK"
2025-04-04 21:14:13,726 - INFO - HTTP Request: POST https://api.groq.com/openai/v1/chat/completions "HTTP/1.1 200 OK"
2025-04-04 21:14:13,964 - INFO - HTTP Request: GET https://adxmtyjibwipeivrxcil.supabase.co/rest/v1/doctors?select=name "HTTP/2 200 OK"
2025-04-04 21:14:30,143 - INFO - HTTP Request: POST https://api.groq.com/openai/v1/chat/completions "HTTP/1.1 200 OK"
2025-04-04 21:14:31,032 - INFO - HTTP Request: GET https://adxmtyjibwipeivrxcil.supabase.co/rest/v1/doctors?select=name "HTTP/2 200 OK"
2025-04-04 21:14:31,258 - INFO - HTTP Request: GET https://adxmtyjibwipeivrxcil.supabase.co/rest/v1/doctors?select=doctor_id&name=eq.Angela+Webb "HTTP/2 200 OK"
2025-04-04 21:14:31,511 - INFO - HTTP Request: GET https://adxmtyjibwipeivrxcil.supabase.co/rest/v1/doctors_slots?select=day%2Ctime&doctor_id=eq.160 "HTTP/2 200 OK"
2025-04-04 21:14:31,751 - INFO - HTTP Request: GET https://adxmtyjibwipeivrxcil.supabase.co/rest/v1/appointments?select=appointment_day%2Cappointment_time&doctor_id=eq.160 "HTTP/2 200 OK"
2025-04-04 21:14:32,622 - INFO - HTTP Request: POST https://api.groq.com/openai/v1/chat/completions "HTTP/1.1 200 OK"
2025-04-04 21:15:10,918 - INFO - HTTP Request: POST https://api.groq.com/openai/v1/chat/completions "HTTP/1.1 200 OK"
